Workbook

Sheet Data
A1: Item ID | B1: Item Name | C1: Category | D1: Stock Quantity | E1: Reorder Level | F1: Unit Price | G1: Supplier | H1: Last Ordered Date | I1: Next Restock Date | J1: Warehouse Location | K1: Stock Status | L1: Stock Value | M1: Month of Last Order | N1: Total Value
A2: ELE0001 | B2: Electronics Item 1 | C2: Category A | D2: 337 | E2: 78 | F2: 17.38 | G2: Supplier X | H2: 44927 | I2: 45094 | J2: Warehouse A | K2: Sufficient | L2: 5857.06 | M2: Jan-2023 | N2: 5857.06
A3: ELE0002 | B3: Electronics Item 2 | C3: Category C | D3: 387 | E3: 76 | F3: 339.97 | G3: Supplier X | H3: 44933 | I3: 45140 | J3: Warehouse C | K3: Sufficient | L3: 131568.39 | M3: Jan-2023 | N3: 131568.39
A4: ELE0003 | B4: Electronics Item 3 | C4: Category A | D4: 226 | E4: 58 | F4: 19.75 | G4: Supplier Z | H4: 44939 | I4: 45102 | J4: Warehouse C | K4: Sufficient | L4: 4463.5 | M4: Jan-2023 | N4: 4463.5
A5: ELE0004 | B5: Electronics Item 4 | C5: Category C | D5: 23 | E5: 193 | F5: 103.42 | G5: Supplier Z | H5: 44945 | I5: 45136 | J5: Warehouse B | K5: Below Reorder | L5: 2378.66 | M5: Jan-2023 | N5: 2378.66
A6: ELE0005 | B6: Electronics Item 5 | C6: Category A | D6: 122 | E6: 164 | F6: 296.69 | G6: Supplier X | H6: 44951 | I6: 45152 | J6: Warehouse C | K6: Below Reorder | L6: 36196.18 | M6: Jan-2023 | N6: 36196.18
A7: ELE0006 | B7: Electronics Item 6 | C7: Category B | D7: 226 | E7: 137 | F7: 142.55 | G7: Supplier X | H7: 44957 | I7: 45120 | J7: Warehouse A | K7: Sufficient | L7: 32216.3 | M7: Jan-2023 | N7: 32216.3
A8: ELE0007 | B8: Electronics Item 7 | C8: Category C | D8: 204 | E8: 74 | F8: 182.69 | G8: Supplier Y | H8: 44963 | I8: 45135 | J8: Warehouse A | K8: Sufficient | L8: 37268.76 | M8: Feb-2023 | N8: 37268.76
A9: ELE0008 | B9: Electronics Item 8 | C9: Category B | D9: 383 | E9: 167 | F9: 270.43 | G9: Supplier X | H9: 44969 | I9: 45178 | J9: Warehouse C | K9: Sufficient | L9: 103574.69 | M9: Feb-2023 | N9: 103574.69
A10: ELE0009 | B10: Electronics Item 9 | C10: Category A | D10: 160 | E10: 142 | F10: 290.79 | G10: Supplier X | H10: 44975 | I10: 45170 | J10: Warehouse C | K10: Sufficient | L10: 46526.4 | M10: Feb-2023 | N10: 46526.4
A11: ELE0010 | B11: Electronics Item 10 | C11: Category A | D11: 126 | E11: 124 | F11: 492.68 | G11: Supplier X | H11: 44981 | I11: 45185 | J11: Warehouse B | K11: Sufficient | L11: 62077.68 | M11: Feb-2023 | N11: 62077.68
A12: ELE0011 | B12: Electronics Item 11 | C12: Category A | D12: 152 | E12: 166 | F12: 319.66 | G12: Supplier Y | H12: 44987 | I12: 45160 | J12: Warehouse B | K12: Below Reorder | L12: 48588.32 | M12: Mar-2023 | N12: 48588.32
A13: ELE0012 | B13: Electronics Item 12 | C13: Category C | D13: 117 | E13: 118 | F13: 352.4 | G13: Supplier X | H13: 44993 | I13: 45186 | J13: Warehouse C | K13: Below Reorder | L13: 41230.8 | M13: Mar-2023 | N13: 41230.8
... A201: ELE0200 | B201: Electronics Item 200 | C201: Category A | D201: 363 | E201: 144 | F201: 112.55 | G201: Supplier Y | H201: 46121 | I201: 46299 | J201: Warehouse A | K201: Sufficient | L201: 40855.65 | M201: Apr-2026 | N201: 40855.65

Sheet ABC Analysis
A1: Item ID | B1: Item Name | C1: Category | D1: Stock Value | E1: Cumulative Value | F1: Cumulative % | G1: ABC Class | I1: ABC Summary
A2: =Data!A32 -> ELE0031 | B2: =Data!B32 -> Electronics Item 31 | C2: =Data!C32 -> Category C | D2: =Data!L32 -> 75937.5 | E2: =D2 -> 75937.5 | F2: =E2/$E$201 -> 0.0056371603 | G2: =IF(F2<=70%,"A",IF(F2<=90%,"B","C")) -> A | I2: Class | J2: No. of Items | K2: Total Stock Value | L2: % of Total Value
A3: =Data!A101 -> ELE0100 | B3: =Data!B101 -> Electronics Item 100 | C3: =Data!C101 -> Category C | D3: =Data!L101 -> 128462.19 | E3: =E2+D3 -> 204399.69 | F3: =E3/$E$201 -> 0.01517345 | G3: =IF(F3<=70%,"A",IF(F3<=90%,"B","C")) -> A | I3: A | J3: =COUNTIF($G$2:$G$201,"A") -> 135 | K3: =SUMIF($G$2:$G$201,"A",$D$2:$D$201) -> 9329988.5 | L3: =K3/$K$6 -> 0.69260432
A4: =Data!A158 -> ELE0157 | B4: =Data!B158 -> Electronics Item 157 | C4: =Data!C158 -> Category B | D4: =Data!L158 -> 85829.7 | E4: =E3+D4 -> 290229.39 | F4: =E4/$E$201 -> 0.02154495 | G4: =IF(F4<=70%,"A",IF(F4<=90%,"B","C")) -> A | I4: B | J4: =COUNTIF($G$2:$G$201,"B") -> 43 | K4: =SUMIF($G$2:$G$201,"B",$D$2:$D$201) -> 2638307.2 | L4: =K4/$K$6 -> 0.19585265
A5: =Data!A64 -> ELE0063 | B5: =Data!B64 -> Electronics Item 63 | C5: =Data!C64 -> Category B | D5: =Data!L64 -> 5787.65 | E5: =E4+D5 -> 296017.04 | F5: =E5/$E$201 -> 0.021974591 | G5: =IF(F5<=70%,"A",IF(F5<=90%,"B","C")) -> A | I5: C | J5: =COUNTIF($G$2:$G$201,"C") -> 22 | K5: =SUMIF($G$2:$G$201,"C",$D$2:$D$201) -> 1502582.5 | L5: =K5/$K$6 -> 0.11154303
A6: =Data!A155 -> ELE0154 | B6: =Data!B155 -> Electronics Item 154 | C6: =Data!C155 -> Category C | D6: =Data!L155 -> 135082.2 | E6: =E5+D6 -> 431099.24 | F6: =E6/$E$201 -> 0.032002312 | G6: =IF(F6<=70%,"A",IF(F6<=90%,"B","C")) -> A | I6: Total | J6: =SUM(J3:J5) -> 200 | K6: =SUM(K3:K5) -> 13470878 | L6: =SUM(L3:L5) -> 1
A7: =Data!A94 -> ELE0093 | B7: =Data!B94 -> Electronics Item 93 | C7: =Data!C94 -> Category A | D7: =Data!L94 -> 9557.6 | E7: =E6+D7 -> 440656.84 | F7: =E7/$E$201 -> 0.032711812 | G7: =IF(F7<=70%,"A",IF(F7<=90%,"B","C")) -> A
A8: =Data!A180 -> ELE0179 | B8: =Data!B180 -> Electronics Item 179 | C8: =Data!C180 -> Category C | D8: =Data!L180 -> 116558.04 | E8: =E7+D8 -> 557214.88 | F8: =E8/$E$201 -> 0.041364407 | G8: =IF(F8<=70%,"A",IF(F8<=90%,"B","C")) -> A
A9: =Data!A3 -> ELE0002 | B9: =Data!B3 -> Electronics Item 2 | C9: =Data!C3 -> Category C | D9: =Data!L3 -> 131568.39 | E9: =E8+D9 -> 688783.27 | F9: =E9/$E$201 -> 0.051131282 | G9: =IF(F9<=70%,"A",IF(F9<=90%,"B","C")) -> A
A10: =Data!A184 -> ELE0183 | B10: =Data!B184 -> Electronics Item 183 | C10: =Data!C184 -> Category B | D10: =Data!L184 -> 198615.76 | E10: =E9+D10 -> 887399.03 | F10: =E10/$E$201 -> 0.065875366 | G10: =IF(F10<=70%,"A",IF(F10<=90%,"B","C")) -> A
A11: =Data!A168 -> ELE0167 | B11: =Data!B168 -> Electronics Item 167 | C11: =Data!C168 -> Category A | D11: =Data!L168 -> 78351.88 | E11: =E10+D11 -> 965750.91 | F11: =E11/$E$201 -> 0.071691756 | G11: =IF(F11<=70%,"A",IF(F11<=90%,"B","C")) -> A
A12: =Data!A21 -> ELE0020 | B12: =Data!B21 -> Electronics Item 20 | C12: =Data!C21 -> Category B | D12: =Data!L21 -> 27320.02 | E12: =E11+D12 -> 993070.93 | F12: =E12/$E$201 -> 0.073719836 | G12: =IF(F12<=70%,"A",IF(F12<=90%,"B","C")) -> A
A13: =Data!A119 -> ELE0118 | B13: =Data!B119 -> Electronics Item 118 | C13: =Data!C119 -> Category B | D13: =Data!L119 -> 24987.63 | E13: =E12+D13 -> 1018058.6 | F13: =E13/$E$201 -> 0.075574773 | G13: =IF(F13<=70%,"A",IF(F13<=90%,"B","C")) -> A
A14: =Data!A90 -> ELE0089 | B14: =Data!B90 -> Electronics Item 89 | C14: =Data!C90 -> Category C | D14: =Data!L90 -> 69845.52 | E14: =E13+D14 -> 1087904.1 | F14: =E14/$E$201 -> 0.0807597 | G14: =IF(F14<=70%,"A",IF(F14<=90%,"B","C")) -> A
A15: =Data!A118 -> ELE0117 | B15: =Data!B118 -> Electronics Item 117 | C15: =Data!C118 -> Category B | D15: =Data!L118 -> 38468.72 | E15: =E14+D15 -> 1126372.8 | F15: =E15/$E$201 -> 0.083615395 | G15: =IF(F15<=70%,"A",IF(F15<=90%,"B","C")) -> A
A16: =Data!A174 -> ELE0173 | B16: =Data!B174 -> Electronics Item 173 | C16: =Data!C174 -> Category B | D16: =Data!L174 -> 89623.38 | E16: =E15+D16 -> 1215996.2 | F16: =E16/$E$201 -> 0.090268516 | G16: =IF(F16<=70%,"A",IF(F16<=90%,"B","C")) -> A
A17: =Data!A129 -> ELE0128 | B17: =Data!B129 -> Electronics Item 128 | C17: =Data!C129 -> Category A | D17: =Data!L129 -> 25169.52 | E17: =E16+D17 -> 1241165.7 | F17: =E17/$E$201 -> 0.092136955 | G17: =IF(F17<=70%,"A",IF(F17<=90%,"B","C")) -> A
A18: =Data!A128 -> ELE0127 | B18: =Data!B128 -> Electronics Item 127 | C18: =Data!C128 -> Category A | D18: =Data!L128 -> 9250.04 | E18: =E17+D18 -> 1250415.7 | F18: =E18/$E$201 -> 0.092823625 | G18: =IF(F18<=70%,"A",IF(F18<=90%,"B","C")) -> A
A19: =Data!A193 -> ELE0192 | B19: =Data!B193 -> Electronics Item 192 | C19: =Data!C193 -> Category A | D19: =Data!L193 -> 4922.46 | E19: =E18+D19 -> 1255338.2 | F19: =E19/$E$201 -> 0.09318904 | G19: =IF(F19<=70%,"A",IF(F19<=90%,"B","C")) -> A
A20: =Data!A10 -> ELE0009 | B20: =Data!B10 -> Electronics Item 9 | C20: =Data!C10 -> Category A | D20: =Data!L10 -> 46526.4 | E20: =E19+D20 -> 1301864.6 | F20: =E20/$E$201 -> 0.09664289 | G20: =IF(F20<=70%,"A",IF(F20<=90%,"B","C")) -> A
A21: =Data!A73 -> ELE0072 | B21: =Data!B73 -> Electronics Item 72 | C21: =Data!C73 -> Category B | D21: =Data!L73 -> 7349.58 | E21: =E20+D21 -> 1309214.2 | F21: =E21/$E$201 -> 0.097188481 | G21: =IF(F21<=70%,"A",IF(F21<=90%,"B","C")) -> A
A22: =Data!A116 -> ELE0115 | B22: =Data!B116 -> Electronics Item 115 | C22: =Data!C116 -> Category C | D22: =Data!L116 -> 106288.84 | E22: =E21+D22 -> 1415503 | F22: =E22/$E$201 -> 0.10507875 | G22: =IF(F22<=70%,"A",IF(F22<=90%,"B","C")) -> A
A23: =Data!A132 -> ELE0131 | B23: =Data!B132 -> Electronics Item 131 | C23: =Data!C132 -> Category B | D23: =Data!L132 -> 8544.33 | E23: =E22+D23 -> 1424047.4 | F23: =E23/$E$201 -> 0.10571303 | G23: =IF(F23<=70%,"A",IF(F23<=90%,"B","C")) -> A
A24: =Data!A89 -> ELE0088 | B24: =Data!B89 -> Electronics Item 88 | C24: =Data!C89 -> Category C | D24: =Data!L89 -> 26165.1 | E24: =E23+D24 -> 1450212.5 | F24: =E24/$E$201 -> 0.10765538 | G24: =IF(F24<=70%,"A",IF(F24<=90%,"B","C")) -> A
A25: =Data!A108 -> ELE0107 | B25: =Data!B108 -> Electronics Item 107 | C25: =Data!C108 -> Category B | D25: =Data!L108 -> 116419.05 | E25: =E24+D25 -> 1566631.5 | F25: =E25/$E$201 -> 0.11629765 | G25: =IF(F25<=70%,"A",IF(F25<=90%,"B","C")) -> A
A26: =Data!A44 -> ELE0043 | B26: =Data!B44 -> Electronics Item 43 | C26: =Data!C44 -> Category A | D26: =Data!L44 -> 28586.4 | E26: =E25+D26 -> 1595217.9 | F26: =E26/$E$201 -> 0.11841974 | G26: =IF(F26<=70%,"A",IF(F26<=90%,"B","C")) -> A
A27: =Data!A111 -> ELE0110 | B27: =Data!B111 -> Electronics Item 110 | C27: =Data!C111 -> Category C | D27: =Data!L111 -> 33087.99 | E27: =E26+D27 -> 1628305.9 | F27: =E27/$E$201 -> 0.120876 | G27: =IF(F27<=70%,"A",IF(F27<=90%,"B","C")) -> A
A28: =Data!A165 -> ELE0164 | B28: =Data!B165 -> Electronics Item 164 | C28: =Data!C165 -> Category B | D28: =Data!L165 -> 25683.24 | E28: =E27+D28 -> 1653989.1 | F28: =E28/$E$201 -> 0.12278258 | G28: =IF(F28<=70%,"A",IF(F28<=90%,"B","C")) -> A
A29: =Data!A99 -> ELE0098 | B29: =Data!B99 -> Electronics Item 98 | C29: =Data!C99 -> Category A | D29: =Data!L99 -> 36285.9 | E29: =E28+D29 -> 1690275 | F29: =E29/$E$201 -> 0.12547623 | G29: =IF(F29<=70%,"A",IF(F29<=90%,"B","C")) -> A | I29: Total Stock Value | J29: Column Labels
A30: =Data!A188 -> ELE0187 | B30: =Data!B188 -> Electronics Item 187 | C30: =Data!C188 -> Category A | D30: =Data!L188 -> 79196.75 | E30: =E29+D30 -> 1769471.8 | F30: =E30/$E$201 -> 0.13135534 | G30: =IF(F30<=70%,"A",IF(F30<=90%,"B","C")) -> A | I30: Row Labels | J30: Below Reorder | K30: Sufficient | L30: Grand Total
A31: =Data!A141 -> ELE0140 | B31: =Data!B141 -> Electronics Item 140 | C31: =Data!C141 -> Category A | D31: =Data!L141 -> 74973.12 | E31: =E30+D31 -> 1844444.9 | F31: =E31/$E$201 -> 0.13692091 | G31: =IF(F31<=70%,"A",IF(F31<=90%,"B","C")) -> A | I31: Category A | J31: 360742.75 | K31: 4394495.7 | L31: 4755238.5
A32: =Data!A7 -> ELE0006 | B32: =Data!B7 -> Electronics Item 6 | C32: =Data!C7 -> Category B | D32: =Data!L7 -> 32216.3 | E32: =E31+D32 -> 1876661.2 | F32: =E32/$E$201 -> 0.13931246 | G32: =IF(F32<=70%,"A",IF(F32<=90%,"B","C")) -> A | I32: Category B | J32: 191371.6 | K32: 3712599.2 | L32: 3903970.8
A33: =Data!A9 -> ELE0008 | B33: =Data!B9 -> Electronics Item 8 | C33: =Data!C9 -> Category B | D33: =Data!L9 -> 103574.69 | E33: =E32+D33 -> 1980235.9 | F33: =E33/$E$201 -> 0.14700125 | G33: =IF(F33<=70%,"A",IF(F33<=90%,"B","C")) -> A | I33: Category C | J33: 478511.62 | K33: 3236788.5 | L33: 3715300.2
A34: =Data!A195 -> ELE0194 | B34: =Data!B195 -> Electronics Item 194 | C34: =Data!C195 -> Category C | D34: =Data!L195 -> 84624.9 | E34: =E33+D34 -> 2064860.8 | F34: =E34/$E$201 -> 0.15328331 | G34: =IF(F34<=70%,"A",IF(F34<=90%,"B","C")) -> A | I34: Grand Total | J34: 1030626 | K34: 11343883 | L34: 12374509
A35: =Data!A102 -> ELE0101 | B35: =Data!B102 -> Electronics Item 101 | C35: =Data!C102 -> Category A | D35: =Data!L102 -> 3752.84 | E35: =E34+D35 -> 2068613.6 | F35: =E35/$E$201 -> 0.1535619 | G35: =IF(F35<=70%,"A",IF(F35<=90%,"B","C")) -> A
A36: =Data!A172 -> ELE0171 | B36: =Data!B172 -> Electronics Item 171 | C36: =Data!C172 -> Category C | D36: =Data!L172 -> 144153.9 | E36: =E35+D36 -> 2212767.5 | F36: =E36/$E$201 -> 0.16426305 | G36: =IF(F36<=70%,"A",IF(F36<=90%,"B","C")) -> A
A37: =Data!A12 -> ELE0011 | B37: =Data!B12 -> Electronics Item 11 | C37: =Data!C12 -> Category A | D37: =Data!L12 -> 48588.32 | E37: =E36+D37 -> 2261355.9 | F37: =E37/$E$201 -> 0.16786997 | G37: =IF(F37<=70%,"A",IF(F37<=90%,"B","C")) -> A
A38: =Data!A191 -> ELE0190 | B38: =Data!B191 -> Electronics Item 190 | C38: =Data!C191 -> Category A | D38: =Data!L191 -> 183410.5 | E38: =E37+D38 -> 2444766.4 | F38: =E38/$E$201 -> 0.1814853 | G38: =IF(F38<=70%,"A",IF(F38<=90%,"B","C")) -> A | I38: Sum of Stock Value | J38: Column Labels
A39: =Data!A135 -> ELE0134 | B39: =Data!B135 -> Electronics Item 134 | C39: =Data!C135 -> Category B | D39: =Data!L135 -> 24161.25 | E39: =E38+D39 -> 2468927.6 | F39: =E39/$E$201 -> 0.18327889 | G39: =IF(F39<=70%,"A",IF(F39<=90%,"B","C")) -> A | I39: Row Labels | J39: Below Reorder | K39: Sufficient | L39: Grand Total
A40: =Data!A138 -> ELE0137 | B40: =Data!B138 -> Electronics Item 137 | C40: =Data!C138 -> Category A | D40: =Data!L138 -> 36727.68 | E40: =E39+D40 -> 2505655.3 | F40: =E40/$E$201 -> 0.18600534 | G40: =IF(F40<=70%,"A",IF(F40<=90%,"B","C")) -> A | I40: Supplier X | J40: 353318.22 | K40: 4666369.4 | L40: 5019687.6
...

Sheet EOQ & Reorder
A1: Item ID | B1: Item Name | C1: Stock Quantity | D1: Reorder Level | E1: Unit Price | F1: Annual Demand | G1: Ordering Cost | H1: Holding Cost Per Unit | I1: EOQ | J1: Calculated Reorder Point | K1: Order Status | M1: EOQ Summary
A2: =Data!A2 -> ELE0001 | B2: =Data!B2 -> Electronics Item 1 | C2: =Data!D2 -> 337 | D2: =Data!E2 -> 78 | E2: =Data!F2 -> 17.38 | F2: =C2*12 -> 4044 | G2: 50 | H2: =E2*20% -> 3.476 | I2: =ROUND(SQRT((2*F2*G2)/H2),0) -> 341 | J2: =ROUND((F2/365)*180,0) -> 1994 | K2: =IF(C2<=D2,"Order Now","Stock OK") -> Stock OK | M2: Metric | N2: Value
A3: =Data!A3 -> ELE0002 | B3: =Data!B3 -> Electronics Item 2 | C3: =Data!D3 -> 387 | D3: =Data!E3 -> 76 | E3: =Data!F3 -> 339.97 | F3: =C3*12 -> 4644 | G3: 50 | H3: =E3*20% -> 67.994 | I3: =ROUND(SQRT((2*F3*G3)/H3),0) -> 83 | J3: =ROUND((F3/365)*180,0) -> 2290 | K3: =IF(C3<=D3,"Order Now","Stock OK") -> Stock OK | M3: Total Items | N3: =COUNTA(A2:A201) -> 200
A4: =Data!A4 -> ELE0003 | B4: =Data!B4 -> Electronics Item 3 | C4: =Data!D4 -> 226 | D4: =Data!E4 -> 58 | E4: =Data!F4 -> 19.75 | F4: =C4*12 -> 2712 | G4: 50 | H4: =E4*20% -> 3.95 | I4: =ROUND(SQRT((2*F4*G4)/H4),0) -> 262 | J4: =ROUND((F4/365)*180,0) -> 1337 | K4: =IF(C4<=D4,"Order Now","Stock OK") -> Stock OK | M4: Items to Order Now | N4: =COUNTIF(K2:K201,"Order Now") -> 47
A5: =Data!A5 -> ELE0004 | B5: =Data!B5 -> Electronics Item 4 | C5: =Data!D5 -> 23 | D5: =Data!E5 -> 193 | E5: =Data!F5 -> 103.42 | F5: =C5*12 -> 276 | G5: 50 | H5: =E5*20% -> 20.684 | I5: =ROUND(SQRT((2*F5*G5)/H5),0) -> 37 | J5: =ROUND((F5/365)*180,0) -> 136 | K5: =IF(C5<=D5,"Order Now","Stock OK") -> Order Now | M5: Items Stock OK | N5: =COUNTIF(K2:K201,"Stock OK") -> 153
A6: =Data!A6 -> ELE0005 | B6: =Data!B6 -> Electronics Item 5 | C6: =Data!D6 -> 122 | D6: =Data!E6 -> 164 | E6: =Data!F6 -> 296.69 | F6: =C6*12 -> 1464 | G6: 50 | H6: =E6*20% -> 59.338 | I6: =ROUND(SQRT((2*F6*G6)/H6),0) -> 50 | J6: =ROUND((F6/365)*180,0) -> 722 | K6: =IF(C6<=D6,"Order Now","Stock OK") -> Order Now | M6: Avg EOQ Quantity | N6: =ROUND(AVERAGE(I2:I201),0) -> 90
A7: =Data!A7 -> ELE0006 | B7: =Data!B7 -> Electronics Item 6 | C7: =Data!D7 -> 226 | D7: =Data!E7 -> 137 | E7: =Data!F7 -> 142.55 | F7: =C7*12 -> 2712 | G7: 50 | H7: =E7*20% -> 28.51 | I7: =ROUND(SQRT((2*F7*G7)/H7),0) -> 98 | J7: =ROUND((F7/365)*180,0) -> 1337 | K7: =IF(C7<=D7,"Order Now","Stock OK") -> Stock OK | M7: Avg Reorder Point | N7: =ROUND(AVERAGE(J2:J201),0) -> 1522
A8: =Data!A8 -> ELE0007 | B8: =Data!B8 -> Electronics Item 7 | C8: =Data!D8 -> 204 | D8: =Data!E8 -> 74 | E8: =Data!F8 -> 182.69 | F8: =C8*12 -> 2448 | G8: 50 | H8: =E8*20% -> 36.538 | I8: =ROUND(SQRT((2*F8*G8)/H8),0) -> 82 | J8: =ROUND((F8/365)*180,0) -> 1207 | K8: =IF(C8<=D8,"Order Now","Stock OK") -> Stock OK
A9: =Data!A9 -> ELE0008 | B9: =Data!B9 -> Electronics Item 8 | C9: =Data!D9 -> 383 | D9: =Data!E9 -> 167 | E9: =Data!F9 -> 270.43 | F9: =C9*12 -> 4596 | G9: 50 | H9: =E9*20% -> 54.086 | I9: =ROUND(SQRT((2*F9*G9)/H9),0) -> 92 | J9: =ROUND((F9/365)*180,0) -> 2267 | K9: =IF(C9<=D9,"Order Now","Stock OK") -> Stock OK
A10: =Data!A10 -> ELE0009 | B10: =Data!B10 -> Electronics Item 9 | C10: =Data!D10 -> 160 | D10: =Data!E10 -> 142 | E10: =Data!F10 -> 290.79 | F10: =C10*12 -> 1920 | G10: 50 | H10: =E10*20% -> 58.158 | I10: =ROUND(SQRT((2*F10*G10)/H10),0) -> 57 | J10: =ROUND((F10/365)*180,0) -> 947 | K10: =IF(C10<=D10,"Order Now","Stock OK") -> Stock OK
A11: =Data!A11 -> ELE0010 | B11: =Data!B11 -> Electronics Item 10 | C11: =Data!D11 -> 126 | D11: =Data!E11 -> 124 | E11: =Data!F11 -> 492.68 | F11: =C11*12 -> 1512 | G11: 50 | H11: =E11*20% -> 98.536 | I11: =ROUND(SQRT((2*F11*G11)/H11),0) -> 39 | J11: =ROUND((F11/365)*180,0) -> 746 | K11: =IF(C11<=D11,"Order Now","Stock OK") -> Stock OK | M11: Sum of Stock Quantity | N11: Column Labels
A12: =Data!A12 -> ELE0011 | B12: =Data!B12 -> Electronics Item 11 | C12: =Data!D12 -> 152 | D12: =Data!E12 -> 166 | E12: =Data!F12 -> 319.66 | F12: =C12*12 -> 1824 | G12: 50 | H12: =E12*20% -> 63.932 | I12: =ROUND(SQRT((2*F12*G12)/H12),0) -> 53 | J12: =ROUND((F12/365)*180,0) -> 900 | K12: =IF(C12<=D12,"Order Now","Stock OK") -> Order Now | M12: Row Labels | N12: Category A | O12: Category B | P12: Category C | Q12: Grand Total
A13: =Data!A13 -> ELE0012 | B13: =Data!B13 -> Electronics Item 12 | C13: =Data!D13 -> 117 | D13: =Data!E13 -> 118 | E13: =Data!F13 -> 352.4 | F13: =C13*12 -> 1404 | G13: 50 | H13: =E13*20% -> 70.48 | I13: =ROUND(SQRT((2*F13*G13)/H13),0) -> 45 | J13: =ROUND((F13/365)*180,0) -> 692 | K13: =IF(C13<=D13,"Order Now","Stock OK") -> Order Now | M13: Supplier X | N13: 8037 | O13: 4668 | P13: 6587 | Q13: 19292
A14: =Data!A14 -> ELE0013 | B14: =Data!B14 -> Electronics Item 13 | C14: =Data!D14 -> 335 | D14: =Data!E14 -> 93 | E14: =Data!F14 -> 269.4 | F14: =C14*12 -> 4020 | G14: 50 | H14: =E14*20% -> 53.88 | I14: =ROUND(SQRT((2*F14*G14)/H14),0) -> 86 | J14: =ROUND((F14/365)*180,0) -> 1982 | K14: =IF(C14<=D14,"Order Now","Stock OK") -> Stock OK | M14: Supplier Y | N14: 6323 | O14: 5798 | P14: 5815 | Q14: 17936
A15: =Data!A15 -> ELE0014 | B15: =Data!B15 -> Electronics Item 14 | C15: =Data!D15 -> 148 | D15: =Data!E15 -> 192 | E15: =Data!F15 -> 113.71 | F15: =C15*12 -> 1776 | G15: 50 | H15: =E15*20% -> 22.742 | I15: =ROUND(SQRT((2*F15*G15)/H15),0) -> 88 | J15: =ROUND((F15/365)*180,0) -> 876 | K15: =IF(C15<=D15,"Order Now","Stock OK") -> Order Now | M15: Supplier Z | N15: 4795 | O15: 3731 | P15: 4525 | Q15: 13051
A16: =Data!A16 -> ELE0015 | B16: =Data!B16 -> Electronics Item 15 | C16: =Data!D16 -> 422 | D16: =Data!E16 -> 130 | E16: =Data!F16 -> 203.58 | F16: =C16*12 -> 5064 | G16: 50 | H16: =E16*20% -> 40.716 | I16: =ROUND(SQRT((2*F16*G16)/H16),0) -> 112 | J16: =ROUND((F16/365)*180,0) -> 2497 | K16: =IF(C16<=D16,"Order Now","Stock OK") -> Stock OK | M16: Grand Total | N16: 19155 | O16: 14197 | P16: 16927 | Q16: 50279
A17: =Data!A17 -> ELE0016 | B17: =Data!B17 -> Electronics Item 16 | C17: =Data!D17 -> 171 | D17: =Data!E17 -> 104 | E17: =Data!F17 -> 329.44 | F17: =C17*12 -> 2052 | G17: 50 | H17: =E17*20% -> 65.888 | I17: =ROUND(SQRT((2*F17*G17)/H17),0) -> 56 | J17: =ROUND((F17/365)*180,0) -> 1012 | K17: =IF(C17<=D17,"Order Now","Stock OK") -> Stock OK
A18: =Data!A18 -> ELE0017 | B18: =Data!B18 -> Electronics Item 17 | C18: =Data!D18 -> 145 | D18: =Data!E18 -> 85 | E18: =Data!F18 -> 127.08 | F18: =C18*12 -> 1740 | G18: 50 | H18: =E18*20% -> 25.416 | I18: =ROUND(SQRT((2*F18*G18)/H18),0) -> 83 | J18: =ROUND((F18/365)*180,0) -> 858 | K18: =IF(C18<=D18,"Order Now","Stock OK") -> Stock OK
A19: =Data!A19 -> ELE0018 | B19: =Data!B19 -> Electronics Item 18 | C19: =Data!D19 -> 309 | D19: =Data!E19 -> 159 | E19: =Data!F19 -> 449.42 | F19: =C19*12 -> 3708 | G19: 50 | H19: =E19*20% -> 89.884 | I19: =ROUND(SQRT((2*F19*G19)/H19),0) -> 64 | J19: =ROUND((F19/365)*180,0) -> 1829 | K19: =IF(C19<=D19,"Order Now","Stock OK") -> Stock OK
A20: =Data!A20 -> ELE0019 | B20: =Data!B20 -> Electronics Item 19 | C20: =Data!D20 -> 270 | D20: =Data!E20 -> 176 | E20: =Data!F20 -> 50 | F20: =C20*12 -> 3240 | G20: 50 | H20: =E20*20% -> 10 | I20: =ROUND(SQRT((2*F20*G20)/H20),0) -> 180 | J20: =ROUND((F20/365)*180,0) -> 1598 | K20: =IF(C20<=D20,"Order Now","Stock OK") -> Stock OK
A21: =Data!A21 -> ELE0020 | B21: =Data!B21 -> Electronics Item 20 | C21: =Data!D21 -> 91 | D21: =Data!E21 -> 158 | E21: =Data!F21 -> 300.22 | F21: =C21*12 -> 1092 | G21: 50 | H21: =E21*20% -> 60.044 | I21: =ROUND(SQRT((2*F21*G21)/H21),0) -> 43 | J21: =ROUND((F21/365)*180,0) -> 539 | K21: =IF(C21<=D21,"Order Now","Stock OK") -> Order Now
A22: =Data!A22 -> ELE0021 | B22: =Data!B22 -> Electronics Item 21 | C22: =Data!D22 -> 280 | D22: =Data!E22 -> 114 | E22: =Data!F22 -> 485.68 | F22: =C22*12 -> 3360 | G22: 50 | H22: =E22*20% -> 97.136 | I22: =ROUND(SQRT((2*F22*G22)/H22),0) -> 59 | J22: =ROUND((F22/365)*180,0) -> 1657 | K22: =IF(C22<=D22,"Order Now","Stock OK") -> Stock OK
A23: =Data!A23 -> ELE0022 | B23: =Data!B23 -> Electronics Item 22 | C23: =Data!D23 -> 68 | D23: =Data!E23 -> 187 | E23: =Data!F23 -> 376.68 | F23: =C23*12 -> 816 | G23: 50 | H23: =E23*20% -> 75.336 | I23: =ROUND(SQRT((2*F23*G23)/H23),0) -> 33 | J23: =ROUND((F23/365)*180,0) -> 402 | K23: =IF(C23<=D23,"Order Now","Stock OK") -> Order Now
A24: =Data!A24 -> ELE0023 | B24: =Data!B24 -> Electronics Item 23 | C24: =Data!D24 -> 160 | D24: =Data!E24 -> 161 | E24: =Data!F24 -> 83.29 | F24: =C24*12 -> 1920 | G24: 50 | H24: =E24*20% -> 16.658 | I24: =ROUND(SQRT((2*F24*G24)/H24),0) -> 107 | J24: =ROUND((F24/365)*180,0) -> 947 | K24: =IF(C24<=D24,"Order Now","Stock OK") -> Order Now
A25: =Data!A25 -> ELE0024 | B25: =Data!B25 -> Electronics Item 24 | C25: =Data!D25 -> 266 | D25: =Data!E25 -> 95 | E25: =Data!F25 -> 256.3 | F25: =C25*12 -> 3192 | G25: 50 | H25: =E25*20% -> 51.26 | I25: =ROUND(SQRT((2*F25*G25)/H25),0) -> 79 | J25: =ROUND((F25/365)*180,0) -> 1574 | K25: =IF(C25<=D25,"Order Now","Stock OK") -> Stock OK
A26: =Data!A26 -> ELE0025 | B26: =Data!B26 -> Electronics Item 25 | C26: =Data!D26 -> 269 | D26: =Data!E26 -> 100 | E26: =Data!F26 -> 80.66 | F26: =C26*12 -> 3228 | G26: 50 | H26: =E26*20% -> 16.132 | I26: =ROUND(SQRT((2*F26*G26)/H26),0) -> 141 | J26: =ROUND((F26/365)*180,0) -> 1592 | K26: =IF(C26<=D26,"Order Now","Stock OK") -> Stock OK
A27: =Data!A27 -> ELE0026 | B27: =Data!B27 -> Electronics Item 26 | C27: =Data!D27 -> 480 | D27: =Data!E27 -> 50 | E27: =Data!F27 -> 301.48 | F27: =C27*12 -> 5760 | G27: 50 | H27: =E27*20% -> 60.296 | I27: =ROUND(SQRT((2*F27*G27)/H27),0) -> 98 | J27: =ROUND((F27/365)*180,0) -> 2841 | K27: =IF(C27<=D27,"Order Now","Stock OK") -> Stock OK
A28: =Data!A28 -> ELE0027 | B28: =Data!B28 -> Electronics Item 27 | C28: =Data!D28 -> 459 | D28: =Data!E28 -> 128 | E28: =Data!F28 -> 123.53 | F28: =C28*12 -> 5508 | G28: 50 | H28: =E28*20% -> 24.706 | I28: =ROUND(SQRT((2*F28*G28)/H28),0) -> 149 | J28: =ROUND((F28/365)*180,0) -> 2716 | K28: =IF(C28<=D28,"Order Now","Stock OK") -> Stock OK
... A201: =Data!A201 -> ELE0200 | B201: =Data!B201 -> Electronics Item 200 | C201: =Data!D201 -> 363 | D201: =Data!E201 -> 144 | E201: =Data!F201 -> 112.55 | F201: =C201*12 -> 4356 | G201: 50 | H201: =E201*20% -> 22.51 | I201: =ROUND(SQRT((2*F201*G201)/H201),0) -> 139 | J201: =ROUND((F201/365)*180,0) -> 2148 | K201: =IF(C201<=D201,"Order Now","Stock OK") -> Stock OK

Sheet Stockout Risk
A1: Item ID | B1: Item Name | C1: Category | D1: Supplier | E1: Stock Quantity | F1: Reorder Level | G1: Stock Value | H1: Stock Status | I1: Risk Score | J1: Risk Level | L1: Stockout Risk Summary
A2: =Data!A2 -> ELE0001 | B2: =Data!B2 -> Electronics Item 1 | C2: =Data!C2 -> Category A | D2: =Data!G2 -> Supplier X | E2: =Data!D2 -> 337 | F2: =Data!E2 -> 78 | G2: =Data!L2 -> 5857.06 | H2: =Data!K2 -> Sufficient | I2: =ROUND(MAX(MIN(((F2-E2)/F2)*100,100),0),0) -> 0 | J2: =IF(H2="Below Reorder","High Risk",IF(I2>0,"Medium Risk","Low Risk")) -> Low Risk | L2: Risk Level | M2: No. of Items | N2: Total Stock Value
A3: =Data!A3 -> ELE0002 | B3: =Data!B3 -> Electronics Item 2 | C3: =Data!C3 -> Category C | D3: =Data!G3 -> Supplier X | E3: =Data!D3 -> 387 | F3: =Data!E3 -> 76 | G3: =Data!L3 -> 131568.39 | H3: =Data!K3 -> Sufficient | I3: =ROUND(MAX(MIN(((F3-E3)/F3)*100,100),0),0) -> 0 | J3: =IF(H3="Below Reorder","High Risk",IF(I3>0,"Medium Risk","Low Risk")) -> Low Risk | L3: High Risk | M3: =COUNTIF($J$2:$J$201,"High Risk") -> 47 | N3: =SUMIF($J$2:$J$201,"High Risk",$G$2:$G$201) -> 859735.45
A4: =Data!A4 -> ELE0003 | B4: =Data!B4 -> Electronics Item 3 | C4: =Data!C4 -> Category A | D4: =Data!G4 -> Supplier Z | E4: =Data!D4 -> 226 | F4: =Data!E4 -> 58 | G4: =Data!L4 -> 4463.5 | H4: =Data!K4 -> Sufficient | I4: =ROUND(MAX(MIN(((F4-E4)/F4)*100,100),0),0) -> 0 | J4: =IF(H4="Below Reorder","High Risk",IF(I4>0,"Medium Risk","Low Risk")) -> Low Risk | L4: Medium Risk | M4: =COUNTIF($J$2:$J$201,"Medium Risk") -> 0 | N4: =SUMIF($J$2:$J$201,"Medium Risk",$G$2:$G$201) -> 0
A5: =Data!A5 -> ELE0004 | B5: =Data!B5 -> Electronics Item 4 | C5: =Data!C5 -> Category C | D5: =Data!G5 -> Supplier Z | E5: =Data!D5 -> 23 | F5: =Data!E5 -> 193 | G5: =Data!L5 -> 2378.66 | H5: =Data!K5 -> Below Reorder | I5: =ROUND(MAX(MIN(((F5-E5)/F5)*100,100),0),0) -> 88 | J5: =IF(H5="Below Reorder","High Risk",IF(I5>0,"Medium Risk","Low Risk")) -> High Risk | L5: Low Risk | M5: =COUNTIF($J$2:$J$201,"Low Risk") -> 153 | N5: =SUMIF($J$2:$J$201,"Low Risk",$G$2:$G$201) -> 12611143
A6: =Data!A6 -> ELE0005 | B6: =Data!B6 -> Electronics Item 5 | C6: =Data!C6 -> Category A | D6: =Data!G6 -> Supplier X | E6: =Data!D6 -> 122 | F6: =Data!E6 -> 164 | G6: =Data!L6 -> 36196.18 | H6: =Data!K6 -> Below Reorder | I6: =ROUND(MAX(MIN(((F6-E6)/F6)*100,100),0),0) -> 26 | J6: =IF(H6="Below Reorder","High Risk",IF(I6>0,"Medium Risk","Low Risk")) -> High Risk | L6: Total | M6: =SUM(M3:M5) -> 200 | N6: =SUM(N3:N5) -> 13470878
A7: =Data!A7 -> ELE0006 | B7: =Data!B7 -> Electronics Item 6 | C7: =Data!C7 -> Category B | D7: =Data!G7 -> Supplier X | E7: =Data!D7 -> 226 | F7: =Data!E7 -> 137 | G7: =Data!L7 -> 32216.3 | H7: =Data!K7 -> Sufficient | I7: =ROUND(MAX(MIN(((F7-E7)/F7)*100,100),0),0) -> 0 | J7: =IF(H7="Below Reorder","High Risk",IF(I7>0,"Medium Risk","Low Risk")) -> Low Risk
A8: =Data!A8 -> ELE0007 | B8: =Data!B8 -> Electronics Item 7 | C8: =Data!C8 -> Category C | D8: =Data!G8 -> Supplier Y | E8: =Data!D8 -> 204 | F8: =Data!E8 -> 74 | G8: =Data!L8 -> 37268.76 | H8: =Data!K8 -> Sufficient | I8: =ROUND(MAX(MIN(((F8-E8)/F8)*100,100),0),0) -> 0 | J8: =IF(H8="Below Reorder","High Risk",IF(I8>0,"Medium Risk","Low Risk")) -> Low Risk
A9: =Data!A9 -> ELE0008 | B9: =Data!B9 -> Electronics Item 8 | C9: =Data!C9 -> Category B | D9: =Data!G9 -> Supplier X | E9: =Data!D9 -> 383 | F9: =Data!E9 -> 167 | G9: =Data!L9 -> 103574.69 | H9: =Data!K9 -> Sufficient | I9: =ROUND(MAX(MIN(((F9-E9)/F9)*100,100),0),0) -> 0 | J9: =IF(H9="Below Reorder","High Risk",IF(I9>0,"Medium Risk","Low Risk")) -> Low Risk
A10: =Data!A10 -> ELE0009 | B10: =Data!B10 -> Electronics Item 9 | C10: =Data!C10 -> Category A | D10: =Data!G10 -> Supplier X | E10: =Data!D10 -> 160 | F10: =Data!E10 -> 142 | G10: =Data!L10 -> 46526.4 | H10: =Data!K10 -> Sufficient | I10: =ROUND(MAX(MIN(((F10-E10)/F10)*100,100),0),0) -> 0 | J10: =IF(H10="Below Reorder","High Risk",IF(I10>0,"Medium Risk","Low Risk")) -> Low Risk
A11: =Data!A11 -> ELE0010 | B11: =Data!B11 -> Electronics Item 10 | C11: =Data!C11 -> Category A | D11: =Data!G11 -> Supplier X | E11: =Data!D11 -> 126 | F11: =Data!E11 -> 124 | G11: =Data!L11 -> 62077.68 | H11: =Data!K11 -> Sufficient | I11: =ROUND(MAX(MIN(((F11-E11)/F11)*100,100),0),0) -> 0 | J11: =IF(H11="Below Reorder","High Risk",IF(I11>0,"Medium Risk","Low Risk")) -> Low Risk | M11: Stock Value by Category and Supplier
A12: =Data!A12 -> ELE0011 | B12: =Data!B12 -> Electronics Item 11 | C12: =Data!C12 -> Category A | D12: =Data!G12 -> Supplier Y | E12: =Data!D12 -> 152 | F12: =Data!E12 -> 166 | G12: =Data!L12 -> 48588.32 | H12: =Data!K12 -> Below Reorder | I12: =ROUND(MAX(MIN(((F12-E12)/F12)*100,100),0),0) -> 8 | J12: =IF(H12="Below Reorder","High Risk",IF(I12>0,"Medium Risk","Low Risk")) -> High Risk | L12: Sum of Stock Value | M12: Column Labels
A13: =Data!A13 -> ELE0012 | B13: =Data!B13 -> Electronics Item 12 | C13: =Data!C13 -> Category C | D13: =Data!G13 -> Supplier X | E13: =Data!D13 -> 117 | F13: =Data!E13 -> 118 | G13: =Data!L13 -> 41230.8 | H13: =Data!K13 -> Below Reorder | I13: =ROUND(MAX(MIN(((F13-E13)/F13)*100,100),0),0) -> 1 | J13: =IF(H13="Below Reorder","High Risk",IF(I13>0,"Medium Risk","Low Risk")) -> High Risk | L13: Row Labels | M13: Supplier X | N13: Supplier Y | O13: Supplier Z | P13: Grand Total
A14: =Data!A14 -> ELE0013 | B14: =Data!B14 -> Electronics Item 13 | C14: =Data!C14 -> Category A | D14: =Data!G14 -> Supplier Y | E14: =Data!D14 -> 335 | F14: =Data!E14 -> 93 | G14: =Data!L14 -> 90249 | H14: =Data!K14 -> Sufficient | I14: =ROUND(MAX(MIN(((F14-E14)/F14)*100,100),0),0) -> 0 | J14: =IF(H14="Below Reorder","High Risk",IF(I14>0,"Medium Risk","Low Risk")) -> Low Risk | L14: Category A | M14: 2085351.1 | N14: 1538783.7 | O14: 1131103.7 | P14: 4755238.5
A15: =Data!A15 -> ELE0014 | B15: =Data!B15 -> Electronics Item 14 | C15: =Data!C15 -> Category A | D15: =Data!G15 -> Supplier X | E15: =Data!D15 -> 148 | F15: =Data!E15 -> 192 | G15: =Data!L15 -> 16829.08 | H15: =Data!K15 -> Below Reorder | I15: =ROUND(MAX(MIN(((F15-E15)/F15)*100,100),0),0) -> 23 | J15: =IF(H15="Below Reorder","High Risk",IF(I15>0,"Medium Risk","Low Risk")) -> High Risk | L15: Category B | M15: 1334678.8 | N15: 1309074 | O15: 1260218 | P15: 3903970.8
A16: =Data!A16 -> ELE0015 | B16: =Data!B16 -> Electronics Item 15 | C16: =Data!C16 -> Category A | D16: =Data!G16 -> Supplier Z | E16: =Data!D16 -> 422 | F16: =Data!E16 -> 130 | G16: =Data!L16 -> 85910.76 | H16: =Data!K16 -> Sufficient | I16: =ROUND(MAX(MIN(((F16-E16)/F16)*100,100),0),0) -> 0 | J16: =IF(H16="Below Reorder","High Risk",IF(I16>0,"Medium Risk","Low Risk")) -> Low Risk | L16: Category C | M16: 1599657.6 | N16: 916312.25 | O16: 1199330.3 | P16: 3715300.2
A17: =Data!A17 -> ELE0016 | B17: =Data!B17 -> Electronics Item 16 | C17: =Data!C17 -> Category C | D17: =Data!G17 -> Supplier Y | E17: =Data!D17 -> 171 | F17: =Data!E17 -> 104 | G17: =Data!L17 -> 56334.24 | H17: =Data!K17 -> Sufficient | I17: =ROUND(MAX(MIN(((F17-E17)/F17)*100,100),0),0) -> 0 | J17: =IF(H17="Below Reorder","High Risk",IF(I17>0,"Medium Risk","Low Risk")) -> Low Risk | L17: Grand Total | M17: 5019687.6 | N17: 3764169.9 | O17: 3590651.9 | P17: 12374509
A18: =Data!A18 -> ELE0017 | B18: =Data!B18 -> Electronics Item 17 | C18: =Data!C18 -> Category C | D18: =Data!G18 -> Supplier Y | E18: =Data!D18 -> 145 | F18: =Data!E18 -> 85 | G18: =Data!L18 -> 18426.6 | H18: =Data!K18 -> Sufficient | I18: =ROUND(MAX(MIN(((F18-E18)/F18)*100,100),0),0) -> 0 | J18: =IF(H18="Below Reorder","High Risk",IF(I18>0,"Medium Risk","Low Risk")) -> Low Risk
A19: =Data!A19 -> ELE0018 | B19: =Data!B19 -> Electronics Item 18 | C19: =Data!C19 -> Category B | D19: =Data!G19 -> Supplier X | E19: =Data!D19 -> 309 | F19: =Data!E19 -> 159 | G19: =Data!L19 -> 138870.78 | H19: =Data!K19 -> Sufficient | I19: =ROUND(MAX(MIN(((F19-E19)/F19)*100,100),0),0) -> 0 | J19: =IF(H19="Below Reorder","High Risk",IF(I19>0,"Medium Risk","Low Risk")) -> Low Risk
A20: =Data!A20 -> ELE0019 | B20: =Data!B20 -> Electronics Item 19 | C20: =Data!C20 -> Category A | D20: =Data!G20 -> Supplier X | E20: =Data!D20 -> 270 | F20: =Data!E20 -> 176 | G20: =Data!L20 -> 13500 | H20: =Data!K20 -> Sufficient | I20: =ROUND(MAX(MIN(((F20-E20)/F20)*100,100),0),0) -> 0 | J20: =IF(H20="Below Reorder","High Risk",IF(I20>0,"Medium Risk","Low Risk")) -> Low Risk
A21: =Data!A21 -> ELE0020 | B21: =Data!B21 -> Electronics Item 20 | C21: =Data!C21 -> Category B | D21: =Data!G21 -> Supplier Z | E21: =Data!D21 -> 91 | F21: =Data!E21 -> 158 | G21: =Data!L21 -> 27320.02 | H21: =Data!K21 -> Below Reorder | I21: =ROUND(MAX(MIN(((F21-E21)/F21)*100,100),0),0) -> 42 | J21: =IF(H21="Below Reorder","High Risk",IF(I21>0,"Medium Risk","Low Risk")) -> High Risk | M21: Stock Quantity by Status and Category
A22: =Data!A22 -> ELE0021 | B22: =Data!B22 -> Electronics Item 21 | C22: =Data!C22 -> Category A | D22: =Data!G22 -> Supplier Z | E22: =Data!D22 -> 280 | F22: =Data!E22 -> 114 | G22: =Data!L22 -> 135990.4 | H22: =Data!K22 -> Sufficient | I22: =ROUND(MAX(MIN(((F22-E22)/F22)*100,100),0),0) -> 0 | J22: =IF(H22="Below Reorder","High Risk",IF(I22>0,"Medium Risk","Low Risk")) -> Low Risk
A23: =Data!A23 -> ELE0022 | B23: =Data!B23 -> Electronics Item 22 | C23: =Data!C23 -> Category C | D23: =Data!G23 -> Supplier Y | E23: =Data!D23 -> 68 | F23: =Data!E23 -> 187 | G23: =Data!L23 -> 25614.24 | H23: =Data!K23 -> Below Reorder | I23: =ROUND(MAX(MIN(((F23-E23)/F23)*100,100),0),0) -> 64 | J23: =IF(H23="Below Reorder","High Risk",IF(I23>0,"Medium Risk","Low Risk")) -> High Risk | L23: Sum of Stock Value | M23: Column Labels
A24: =Data!A24 -> ELE0023 | B24: =Data!B24 -> Electronics Item 23 | C24: =Data!C24 -> Category C | D24: =Data!G24 -> Supplier Z | E24: =Data!D24 -> 160 | F24: =Data!E24 -> 161 | G24: =Data!L24 -> 13326.4 | H24: =Data!K24 -> Below Reorder | I24: =ROUND(MAX(MIN(((F24-E24)/F24)*100,100),0),0) -> 1 | J24: =IF(H24="Below Reorder","High Risk",IF(I24>0,"Medium Risk","Low Risk")) -> High Risk | L24: Row Labels | M24: Category A | N24: Category B | O24: Category C | P24: Grand Total
A25: =Data!A25 -> ELE0024 | B25: =Data!B25 -> Electronics Item 24 | C25: =Data!C25 -> Category C | D25: =Data!G25 -> Supplier Y | E25: =Data!D25 -> 266 | F25: =Data!E25 -> 95 | G25: =Data!L25 -> 68175.8 | H25: =Data!K25 -> Sufficient | I25: =ROUND(MAX(MIN(((F25-E25)/F25)*100,100),0),0) -> 0 | J25: =IF(H25="Below Reorder","High Risk",IF(I25>0,"Medium Risk","Low Risk")) -> Low Risk | L25: Below Reorder | M25: 360742.75 | N25: 191371.6 | O25: 478511.62 | P25: 1030626
A26: =Data!A26 -> ELE0025 | B26: =Data!B26 -> Electronics Item 25 | C26: =Data!C26 -> Category A | D26: =Data!G26 -> Supplier Z | E26: =Data!D26 -> 269 | F26: =Data!E26 -> 100 | G26: =Data!L26 -> 21697.54 | H26: =Data!K26 -> Sufficient | I26: =ROUND(MAX(MIN(((F26-E26)/F26)*100,100),0),0) -> 0 | J26: =IF(H26="Below Reorder","High Risk",IF(I26>0,"Medium Risk","Low Risk")) -> Low Risk | L26: Sufficient | M26: 4394495.7 | N26: 3712599.2 | O26: 3236788.5 | P26: 11343883
A27: =Data!A27 -> ELE0026 | B27: =Data!B27 -> Electronics Item 26 | C27: =Data!C27 -> Category A | D27: =Data!G27 -> Supplier X | E27: =Data!D27 -> 480 | F27: =Data!E27 -> 50 | G27: =Data!L27 -> 144710.4 | H27: =Data!K27 -> Sufficient | I27: =ROUND(MAX(MIN(((F27-E27)/F27)*100,100),0),0) -> 0 | J27: =IF(H27="Below Reorder","High Risk",IF(I27>0,"Medium Risk","Low Risk")) -> Low Risk | L27: Grand Total | M27: 4755238.5 | N27: 3903970.8 | O27: 3715300.2 | P27: 12374509
A28: =Data!A28 -> ELE0027 | B28: =Data!B28 -> Electronics Item 27 | C28: =Data!C28 -> Category C | D28: =Data!G28 -> Supplier X | E28: =Data!D28 -> 459 | F28: =Data!E28 -> 128 | G28: =Data!L28 -> 56700.27 | H28: =Data!K28 -> Sufficient | I28: =ROUND(MAX(MIN(((F28-E28)/F28)*100,100),0),0) -> 0 | J28: =IF(H28="Below Reorder","High Risk",IF(I28>0,"Medium Risk","Low Risk")) -> Low Risk
A29: =Data!A29 -> ELE0028 | B29: =Data!B29 -> Electronics Item 28 | C29: =Data!C29 -> Category C | D29: =Data!G29 -> Supplier X | E29: =Data!D29 -> 384 | F29: =Data!E29 -> 174 | G29: =Data!L29 -> 157029.12 | H29: =Data!K29 -> Sufficient | I29: =ROUND(MAX(MIN(((F29-E29)/F29)*100,100),0),0) -> 0 | J29: =IF(H29="Below Reorder","High Risk",IF(I29>0,"Medium Risk","Low Risk")) -> Low Risk
A30: =Data!A30 -> ELE0029 | B30: =Data!B30 -> Electronics Item 29 | C30: =Data!C30 -> Category B | D30: =Data!G30 -> Supplier Z | E30: =Data!D30 -> 347 | F30: =Data!E30 -> 171 | G30: =Data!L30 -> 164370.43 | H30: =Data!K30 -> Sufficient | I30: =ROUND(MAX(MIN(((F30-E30)/F30)*100,100),0),0) -> 0 | J30: =IF(H30="Below Reorder","High Risk",IF(I30>0,"Medium Risk","Low Risk")) -> Low Risk
A31: =Data!A31 -> ELE0030 | B31: =Data!B31 -> Electronics Item 30 | C31: =Data!C31 -> Category C | D31: =Data!G31 -> Supplier Z | E31: =Data!D31 -> 226 | F31: =Data!E31 -> 104 | G31: =Data!L31 -> 105047.06 | H31: =Data!K31 -> Sufficient | I31: =ROUND(MAX(MIN(((F31-E31)/F31)*100,100),0),0) -> 0 | J31: =IF(H31="Below Reorder","High Risk",IF(I31>0,"Medium Risk","Low Risk")) -> Low Risk
A32: =Data!A32 -> ELE0031 | B32: =Data!B32 -> Electronics Item 31 | C32: =Data!C32 -> Category C | D32: =Data!G32 -> Supplier Y | E32: =Data!D32 -> 375 | F32: =Data!E32 -> 129 | G32: =Data!L32 -> 75937.5 | H32: =Data!K32 -> Sufficient | I32: =ROUND(MAX(MIN(((F32-E32)/F32)*100,100),0),0) -> 0 | J32: =IF(H32="Below Reorder","High Risk",IF(I32>0,"Medium Risk","Low Risk")) -> Low Risk
A33: =Data!A33 -> ELE0032 | B33: =Data!B33 -> Electronics Item 32 | C33: =Data!C33 -> Category A | D33: =Data!G33 -> Supplier X | E33: =Data!D33 -> 470 | F33: =Data!E33 -> 182 | G33: =Data!L33 -> 107390.3 | H33: =Data!K33 -> Sufficient | I33: =ROUND(MAX(MIN(((F33-E33)/F33)*100,100),0),0) -> 0 | J33: =IF(H33="Below Reorder","High Risk",IF(I33>0,"Medium Risk","Low Risk")) -> Low Risk
A34: =Data!A34 -> ELE0033 | B34: =Data!B34 -> Electronics Item 33 | C34: =Data!C34 -> Category A | D34: =Data!G34 -> Supplier X | E34: =Data!D34 -> 20 | F34: =Data!E34 -> 200 | G34: =Data!L34 -> 5583.8 | H34: =Data!K34 -> Below Reorder | I34: =ROUND(MAX(MIN(((F34-E34)/F34)*100,100),0),0) -> 90 | J34: =IF(H34="Below Reorder","High Risk",IF(I34>0,"Medium Risk","Low Risk")) -> High Risk
A35: =Data!A35 -> ELE0034 | B35: =Data!B35 -> Electronics Item 34 | C35: =Data!C35 -> Category A | D35: =Data!G35 -> Supplier Y | E35: =Data!D35 -> 372 | F35: =Data!E35 -> 65 | G35: =Data!L35 -> 44018.76 | H35: =Data!K35 -> Sufficient | I35: =ROUND(MAX(MIN(((F35-E35)/F35)*100,100),0),0) -> 0 | J35: =IF(H35="Below Reorder","High Risk",IF(I35>0,"Medium Risk","Low Risk")) -> Low Risk
A36: =Data!A36 -> ELE0035 | B36: =Data!B36 -> Electronics Item 35 | C36: =Data!C36 -> Category A | D36: =Data!G36 -> Supplier Z | E36: =Data!D36 -> 273 | F36: =Data!E36 -> 110 | G36: =Data!L36 -> 38998.05 | H36: =Data!K36 -> Sufficient | I36: =ROUND(MAX(MIN(((F36-E36)/F36)*100,100),0),0) -> 0 | J36: =IF(H36="Below Reorder","High Risk",IF(I36>0,"Medium Risk","Low Risk")) -> Low Risk
A37: =Data!A37 -> ELE0036 | B37: =Data!B37 -> Electronics Item 36 | C37: =Data!C37 -> Category B | D37: =Data!G37 -> Supplier Y | E37: =Data!D37 -> 380 | F37: =Data!E37 -> 196 | G37: =Data!L37 -> 110283.6 | H37: =Data!K37 -> Sufficient | I37: =ROUND(MAX(MIN(((F37-E37)/F37)*100,100),0),0) -> 0 | J37: =IF(H37="Below Reorder","High Risk",IF(I37>0,"Medium Risk","Low Risk")) -> Low Risk
A38: =Data!A38 -> ELE0037 | B38: =Data!B38 -> Electronics Item 37 | C38: =Data!C38 -> Category B | D38: =Data!G38 -> Supplier Y | E38: =Data!D38 -> 58 | F38: =Data!E38 -> 74 | G38: =Data!L38 -> 19209.6 | H38: =Data!K38 -> Below Reorder | I38: =ROUND(MAX(MIN(((F38-E38)/F38)*100,100),0),0) -> 22 | J38: =IF(H38="Below Reorder","High Risk",IF(I38>0,"Medium Risk","Low Risk")) -> High Risk
A39: =Data!A39 -> ELE0038 | B39: =Data!B39 -> Electronics Item 38 | C39: =Data!C39 -> Category A | D39: =Data!G39 -> Supplier X | E39: =Data!D39 -> 452 | F39: =Data!E39 -> 63 | G39: =Data!L39 -> 152920.64 | H39: =Data!K39 -> Sufficient | I39: =ROUND(MAX(MIN(((F39-E39)/F39)*100,100),0),0) -> 0 | J39: =IF(H39="Below Reorder","High Risk",IF(I39>0,"Medium Risk","Low Risk")) -> Low Risk
... A201: =Data!A201 -> ELE0200 | B201: =Data!B201 -> Electronics Item 200 | C201: =Data!C201 -> Category A | D201: =Data!G201 -> Supplier Y | E201: =Data!D201 -> 363 | F201: =Data!E201 -> 144 | G201: =Data!L201 -> 40855.65 | H201: =Data!K201 -> Sufficient | I201: =ROUND(MAX(MIN(((F201-E201)/F201)*100,100),0),0) -> 0 | J201: =IF(H201="Below Reorder","High Risk",IF(I201>0,"Medium Risk","Low Risk")) -> Low Risk

Sheet Dashboard
B2: Inventory Management Dashboard
B3: Electronics Division | Jan 2023 – Apr 2026 | 200 SKUs
B5: 200 | E5: =ROUND(SUM(Data!L2:L201),0) -> 13470878 | J5: =COUNTIF('EOQ & Reorder'!K2:K201,"Order Now") -> 47 | N5: =COUNTIF('Stockout Risk'!J2:J201,"High Risk") -> 47
B8: Total SKUs | E8: Total Stock Value ($) | J8: Items to Order Now | N8: High Risk Items
